<?xml version="1.0" ?>
<!-- =================================================================================== -->
<!-- |    This document was autogenerated by xacro from panda_arm_hand.urdf.xacro      | -->
<!-- |    EDITING THIS FILE BY HAND IS NOT RECOMMENDED                                 | -->
<!-- =================================================================================== -->
<robot name="arm" xmlns:xacro="http://www.ros.org/wiki/xacro">
  <link name="base_link0">
    <visual>
      <geometry>
        <mesh filename="Models/6_DOF_arm/BASE.stl"/>
      </geometry>
      <material name="panda_white"/>
    </visual>
    <collision>
      <geometry>
        <mesh filename="Models/6_DOF_arm/BASE.stl"/>
      </geometry>
      <material name="panda_white"/>
    </collision>
  </link>

  <link name="shoulder_link1">
    <visual>
      <geometry>
        <mesh filename="Models/6_DOF_arm/SHOULDER.stl"/>
      </geometry>
      <material name="panda_white"/>
    </visual>
    <collision>
      <geometry>
        <mesh filename="Models/6_DOF_arm/SHOULDER.stl"/>
      </geometry>
      <material name="panda_white"/>
    </collision>
  </link>
  <joint name="shoulder_joint1" type="revolute">
    <safety_controller k_position="100.0" k_velocity="40.0" soft_lower_limit="-2.8973" soft_upper_limit="2.8973"/>
    <origin rpy="0 0 0" xyz="0 0 0.086"/>
    <parent link="base_link0"/>
    <child link="shoulder_link1"/>
    <axis xyz="0 0 1"/>
    <limit effort="87" lower="-2.9671" upper="2.9671" velocity="2.1750"/>
  </joint>

  <link name="bicep_link2">
    <visual>
      <geometry>
        <mesh filename="Models/6_DOF_arm/BICEP.stl"/>
      </geometry>
      <material name="panda_white"/>
    </visual>
    <collision>
      <geometry>
        <mesh filename="Models/6_DOF_arm/BICEP.stl"/>
      </geometry>
      <material name="panda_white"/>
    </collision>
  </link>
  <joint name="bicep_joint2" type="revolute">
    <safety_controller k_position="100.0" k_velocity="40.0" soft_lower_limit="-1.7628" soft_upper_limit="1.7628"/>
    <origin rpy="-1.57079632679 0 3.1415926535" xyz="0.02293 0.032 0.048"/>
    <parent link="shoulder_link1"/>
    <child link="bicep_link2"/>
    <axis xyz="0 0 1"/>
    <limit effort="87" lower="-1.8326" upper="1.8326" velocity="2.1750"/>
  </joint>

  <link name="elbow_link3">
    <visual>
      <geometry>
        <mesh filename="Models/6_DOF_arm/ELBOW.stl"/>
      </geometry>
      <material name="panda_white"/>
    </visual>
    <collision>
      <geometry>
        <mesh filename="Models/6_DOF_arm/ELBOW.stl"/>
      </geometry>
      <material name="panda_white"/>
    </collision>
  </link>
  <joint name="elbow_joint3" type="revolute">
    <safety_controller k_position="100.0" k_velocity="40.0" soft_lower_limit="-2.8973" soft_upper_limit="2.8973"/>
    <origin rpy="3.1415926535 0 -1.57079632679" xyz="0.00089 0.3 -0.03588"/>
    <parent link="bicep_link2"/>
    <child link="elbow_link3"/>
    <axis xyz="0 0 1"/>
    <limit effort="87" lower="-2.9671" upper="2.9671" velocity="2.1750"/>
  </joint>

  <link name="forearm_link4">
    <visual>
      <geometry>
        <mesh filename="Models/6_DOF_arm/FOREARM.stl"/>
      </geometry>
      <material name="panda_white"/>
    </visual>
    <collision>
      <geometry>
        <mesh filename="Models/6_DOF_arm/FOREARM.stl"/>
      </geometry>
      <material name="panda_white"/>
    </collision>
  </link>
  <joint name="forearm_joint4" type="revolute">
    <safety_controller k_position="100.0" k_velocity="40.0" soft_lower_limit="-3.0718" soft_upper_limit="-0.0698"/>
    <origin rpy="1.57079632679 1.57079632679 0" xyz="0.011 0.00078 0.03499"/>
    <parent link="elbow_link3"/>
    <child link="forearm_link4"/>
    <axis xyz="0 0 1"/>
    <limit effort="87" lower="-3.1416" upper="0.0" velocity="2.1750"/>
  </joint>

  <link name="wrist_link5">
    <visual>
      <geometry>
        <mesh filename="Models/6_DOF_arm/WRIST.stl"/>
      </geometry>
      <material name="panda_white"/>
    </visual>
    <collision>
      <geometry>
        <mesh filename="Models/6_DOF_arm/WRIST.stl"/>
      </geometry>
      <material name="panda_white"/>
    </collision>
  </link>
  <joint name="wrist_joint5" type="revolute">
    <safety_controller k_position="100.0" k_velocity="40.0" soft_lower_limit="-2.8973" soft_upper_limit="2.8973"/>
    <origin rpy="-1.57079632679 0 -1.57079632679" xyz="-0.0006 -0.02699 0.28602"/>
    <parent link="forearm_link4"/>
    <child link="wrist_link5"/>
    <axis xyz="0 0 1"/>
    <limit effort="12" lower="-2.9671" upper="2.9671" velocity="2.6100"/>
  </joint>

  <link name="palm_link6">
    <visual>
      <geometry>
        <mesh filename="Models/6_DOF_arm/PALM.stl"/>
      </geometry>
      <material name="panda_white"/>
    </visual>
    <collision>
      <geometry>
        <mesh filename="Models/6_DOF_arm/PALM.stl"/>
      </geometry>
      <material name="panda_white"/>
    </collision>
  </link>
  <joint name="ee_joint" type="revolute">
    <safety_controller k_position="100.0" k_velocity="40.0" soft_lower_limit="-0.0175" soft_upper_limit="3.7525"/>
    <origin rpy="0 1.57079632679 -1.57079632679" xyz="0.06308 0.00065 0.02694"/>
    <parent link="wrist_link5"/>
    <child link="palm_link6"/>
    <axis xyz="0 0 1"/>
    <limit effort="12" lower="-0.0873" upper="3.8223" velocity="2.6100"/>
  </joint>

  <link name="hand_leftfinger">
    <visual>
      <geometry>
        <mesh filename="Models/6_DOF_arm/FINGER.stl"/>
      </geometry>
      <material name="panda_white"/>
    </visual>
    <collision>
      <geometry>
        <mesh filename="Models/6_DOF_arm/FINGER.stl"/>
      </geometry>
      <material name="panda_white"/>
    </collision>
  </link>
  <joint name="hand_leftfinger_joint" type="prismatic">
    <origin rpy="1.57079632679 0 0" xyz="0.00474 -0.00044 0.0712"/>
    <parent link="palm_link6"/>
    <child link="hand_leftfinger"/>
    <axis xyz="0 0 1"/>
    <limit effort="20" lower="0.0" upper="0.04" velocity="0.2"/>
  </joint>

  <link name="hand_rightfinger">
    <visual>
      <geometry>
        <mesh filename="Models/6_DOF_arm/FINGER.stl"/>
      </geometry>
      <material name="panda_white"/>
    </visual>
    <collision>
      <geometry>
        <mesh filename="Models/6_DOF_arm/FINGER.stl"/>
      </geometry>
      <material name="panda_white"/>
    </collision>
  </link>
  <joint name="hand_rightfinger_joint" type="prismatic">
    <origin rpy="-1.57079632679 0 3.14159265348" xyz="0.00474 0.00044 0.0712"/>
    <parent link="palm_link6"/>
    <child link="hand_rightfinger"/>
    <axis xyz="0 0 1"/>
    <limit effort="20" lower="0.0" upper="0.04" velocity="0.2"/>
  </joint>

  <material name="panda_white">
    <color rgba="1. 1. 1. 1."/>
  </material>
</robot>